2025-10-09 10:30:06,359 | INFO | GET / | Status: 404 | Duration: 0.001s
2025-10-09 10:30:43,589 | INFO | GET /students | Status: 404 | Duration: 0.0s
2025-10-09 10:30:49,238 | INFO | GET /students | Status: 404 | Duration: 0.0s
2025-10-09 10:31:01,607 | INFO | GET /error-demo | Status: 404 | Duration: 0.0s
2025-10-09 10:34:47,562 | INFO | GET / | Status: 404 | Duration: 0.0s
2025-10-09 10:40:20,273 | INFO | GET / | Status: 404 | Duration: 0.001s
2025-10-09 10:40:32,393 | INFO | GET /students | Status: 404 | Duration: 0.0s
2025-10-09 10:41:15,806 | INFO | GET /students | Status: 404 | Duration: 0.0s
2025-10-09 10:41:31,507 | INFO | GET /error-demo | Status: 404 | Duration: 0.0s
2025-10-09 10:43:06,102 | INFO | GET /students | Status: 404 | Duration: 0.0s
2025-10-09 10:47:39,894 | INFO | Fetching all students from database...
2025-10-09 10:47:39,895 | INFO | GET /students | Status: 200 | Duration: 0.022s
2025-10-09 10:47:53,069 | ERROR | Exception in GET /error-demo: Simulated error for testing logs
Traceback (most recent call last):
  File "C:\Users\user1\PycharmProjects\AsyncAwait\.venv\Lib\site-packages\starlette\middleware\base.py", line 151, in call_next
    message = await recv_stream.receive()
              ^^^^^^^^^^^^^^^^^^^^^^^^^^^
  File "C:\Users\user1\PycharmProjects\AsyncAwait\.venv\Lib\site-packages\anyio\streams\memory.py", line 126, in receive
    raise EndOfStream from None
anyio.EndOfStream

During handling of the above exception, another exception occurred:

Traceback (most recent call last):
  File "C:\Users\user1\PycharmProjects\AsyncAwait\middleware.py", line 21, in log_requests
    response = await call_next(request)
               ^^^^^^^^^^^^^^^^^^^^^^^^
  File "C:\Users\user1\PycharmProjects\AsyncAwait\.venv\Lib\site-packages\starlette\middleware\base.py", line 159, in call_next
    raise app_exc
  File "C:\Users\user1\PycharmProjects\AsyncAwait\.venv\Lib\site-packages\starlette\middleware\base.py", line 144, in coro
    await self.app(scope, receive_or_disconnect, send_no_error)
  File "C:\Users\user1\PycharmProjects\AsyncAwait\.venv\Lib\site-packages\starlette\middleware\exceptions.py", line 63, in __call__
    await wrap_app_handling_exceptions(self.app, conn)(scope, receive, send)
  File "C:\Users\user1\PycharmProjects\AsyncAwait\.venv\Lib\site-packages\starlette\_exception_handler.py", line 53, in wrapped_app
    raise exc
  File "C:\Users\user1\PycharmProjects\AsyncAwait\.venv\Lib\site-packages\starlette\_exception_handler.py", line 42, in wrapped_app
    await app(scope, receive, sender)
  File "C:\Users\user1\PycharmProjects\AsyncAwait\.venv\Lib\site-packages\fastapi\middleware\asyncexitstack.py", line 18, in __call__
    await self.app(scope, receive, send)
  File "C:\Users\user1\PycharmProjects\AsyncAwait\.venv\Lib\site-packages\starlette\routing.py", line 716, in __call__
    await self.middleware_stack(scope, receive, send)
  File "C:\Users\user1\PycharmProjects\AsyncAwait\.venv\Lib\site-packages\starlette\routing.py", line 736, in app
    await route.handle(scope, receive, send)
  File "C:\Users\user1\PycharmProjects\AsyncAwait\.venv\Lib\site-packages\starlette\routing.py", line 290, in handle
    await self.app(scope, receive, send)
  File "C:\Users\user1\PycharmProjects\AsyncAwait\.venv\Lib\site-packages\fastapi\routing.py", line 123, in app
    await wrap_app_handling_exceptions(app, request)(scope, receive, send)
  File "C:\Users\user1\PycharmProjects\AsyncAwait\.venv\Lib\site-packages\starlette\_exception_handler.py", line 53, in wrapped_app
    raise exc
  File "C:\Users\user1\PycharmProjects\AsyncAwait\.venv\Lib\site-packages\starlette\_exception_handler.py", line 42, in wrapped_app
    await app(scope, receive, sender)
  File "C:\Users\user1\PycharmProjects\AsyncAwait\.venv\Lib\site-packages\fastapi\routing.py", line 109, in app
    response = await f(request)
               ^^^^^^^^^^^^^^^^
  File "C:\Users\user1\PycharmProjects\AsyncAwait\.venv\Lib\site-packages\fastapi\routing.py", line 387, in app
    raw_response = await run_endpoint_function(
                   ^^^^^^^^^^^^^^^^^^^^^^^^^^^^
    ...<3 lines>...
    )
    ^
  File "C:\Users\user1\PycharmProjects\AsyncAwait\.venv\Lib\site-packages\fastapi\routing.py", line 290, in run_endpoint_function
    return await run_in_threadpool(dependant.call, **values)
           ^^^^^^^^^^^^^^^^^^^^^^^^^^^^^^^^^^^^^^^^^^^^^^^^^
  File "C:\Users\user1\PycharmProjects\AsyncAwait\.venv\Lib\site-packages\starlette\concurrency.py", line 38, in run_in_threadpool
    return await anyio.to_thread.run_sync(func)
           ^^^^^^^^^^^^^^^^^^^^^^^^^^^^^^^^^^^^
  File "C:\Users\user1\PycharmProjects\AsyncAwait\.venv\Lib\site-packages\anyio\to_thread.py", line 56, in run_sync
    return await get_async_backend().run_sync_in_worker_thread(
           ^^^^^^^^^^^^^^^^^^^^^^^^^^^^^^^^^^^^^^^^^^^^^^^^^^^^
        func, args, abandon_on_cancel=abandon_on_cancel, limiter=limiter
        ^^^^^^^^^^^^^^^^^^^^^^^^^^^^^^^^^^^^^^^^^^^^^^^^^^^^^^^^^^^^^^^^
    )
    ^
  File "C:\Users\user1\PycharmProjects\AsyncAwait\.venv\Lib\site-packages\anyio\_backends\_asyncio.py", line 2485, in run_sync_in_worker_thread
    return await future
           ^^^^^^^^^^^^
  File "C:\Users\user1\PycharmProjects\AsyncAwait\.venv\Lib\site-packages\anyio\_backends\_asyncio.py", line 976, in run
    result = context.run(func, *args)
  File "C:\Users\user1\PycharmProjects\AsyncAwait\middleware.py", line 44, in error_demo
    raise ValueError("Simulated error for testing logs")
ValueError: Simulated error for testing logs

2025-10-09 10:47:53,108 | ERROR | Unhandled error in /error-demo: Simulated error for testing logs
  + Exception Group Traceback (most recent call last):
  |   File "C:\Users\user1\PycharmProjects\AsyncAwait\.venv\Lib\site-packages\starlette\_utils.py", line 79, in collapse_excgroups
  |     yield
  |   File "C:\Users\user1\PycharmProjects\AsyncAwait\.venv\Lib\site-packages\starlette\middleware\base.py", line 183, in __call__
  |     async with anyio.create_task_group() as task_group:
  |                ~~~~~~~~~~~~~~~~~~~~~~~^^
  |   File "C:\Users\user1\PycharmProjects\AsyncAwait\.venv\Lib\site-packages\anyio\_backends\_asyncio.py", line 781, in __aexit__
  |     raise BaseExceptionGroup(
  |         "unhandled errors in a TaskGroup", self._exceptions
  |     ) from None
  | ExceptionGroup: unhandled errors in a TaskGroup (1 sub-exception)
  +-+---------------- 1 ----------------
    | Traceback (most recent call last):
    |   File "C:\Users\user1\PycharmProjects\AsyncAwait\.venv\Lib\site-packages\starlette\middleware\errors.py", line 164, in __call__
    |     await self.app(scope, receive, _send)
    |   File "C:\Users\user1\PycharmProjects\AsyncAwait\.venv\Lib\site-packages\starlette\middleware\base.py", line 182, in __call__
    |     with recv_stream, send_stream, collapse_excgroups():
    |                                    ~~~~~~~~~~~~~~~~~~^^
    |   File "C:\Users\user1\AppData\Local\Programs\Python\Python313\Lib\contextlib.py", line 162, in __exit__
    |     self.gen.throw(value)
    |     ~~~~~~~~~~~~~~^^^^^^^
    |   File "C:\Users\user1\PycharmProjects\AsyncAwait\.venv\Lib\site-packages\starlette\_utils.py", line 85, in collapse_excgroups
    |     raise exc
    |   File "C:\Users\user1\PycharmProjects\AsyncAwait\.venv\Lib\site-packages\starlette\middleware\base.py", line 184, in __call__
    |     response = await self.dispatch_func(request, call_next)
    |                ^^^^^^^^^^^^^^^^^^^^^^^^^^^^^^^^^^^^^^^^^^^^
    |   File "C:\Users\user1\PycharmProjects\AsyncAwait\middleware.py", line 27, in log_requests
    |     raise e
    |   File "C:\Users\user1\PycharmProjects\AsyncAwait\middleware.py", line 21, in log_requests
    |     response = await call_next(request)
    |                ^^^^^^^^^^^^^^^^^^^^^^^^
    |   File "C:\Users\user1\PycharmProjects\AsyncAwait\.venv\Lib\site-packages\starlette\middleware\base.py", line 159, in call_next
    |     raise app_exc
    |   File "C:\Users\user1\PycharmProjects\AsyncAwait\.venv\Lib\site-packages\starlette\middleware\base.py", line 144, in coro
    |     await self.app(scope, receive_or_disconnect, send_no_error)
    |   File "C:\Users\user1\PycharmProjects\AsyncAwait\.venv\Lib\site-packages\starlette\middleware\exceptions.py", line 63, in __call__
    |     await wrap_app_handling_exceptions(self.app, conn)(scope, receive, send)
    |   File "C:\Users\user1\PycharmProjects\AsyncAwait\.venv\Lib\site-packages\starlette\_exception_handler.py", line 53, in wrapped_app
    |     raise exc
    |   File "C:\Users\user1\PycharmProjects\AsyncAwait\.venv\Lib\site-packages\starlette\_exception_handler.py", line 42, in wrapped_app
    |     await app(scope, receive, sender)
    |   File "C:\Users\user1\PycharmProjects\AsyncAwait\.venv\Lib\site-packages\fastapi\middleware\asyncexitstack.py", line 18, in __call__
    |     await self.app(scope, receive, send)
    |   File "C:\Users\user1\PycharmProjects\AsyncAwait\.venv\Lib\site-packages\starlette\routing.py", line 716, in __call__
    |     await self.middleware_stack(scope, receive, send)
    |   File "C:\Users\user1\PycharmProjects\AsyncAwait\.venv\Lib\site-packages\starlette\routing.py", line 736, in app
    |     await route.handle(scope, receive, send)
    |   File "C:\Users\user1\PycharmProjects\AsyncAwait\.venv\Lib\site-packages\starlette\routing.py", line 290, in handle
    |     await self.app(scope, receive, send)
    |   File "C:\Users\user1\PycharmProjects\AsyncAwait\.venv\Lib\site-packages\fastapi\routing.py", line 123, in app
    |     await wrap_app_handling_exceptions(app, request)(scope, receive, send)
    |   File "C:\Users\user1\PycharmProjects\AsyncAwait\.venv\Lib\site-packages\starlette\_exception_handler.py", line 53, in wrapped_app
    |     raise exc
    |   File "C:\Users\user1\PycharmProjects\AsyncAwait\.venv\Lib\site-packages\starlette\_exception_handler.py", line 42, in wrapped_app
    |     await app(scope, receive, sender)
    |   File "C:\Users\user1\PycharmProjects\AsyncAwait\.venv\Lib\site-packages\fastapi\routing.py", line 109, in app
    |     response = await f(request)
    |                ^^^^^^^^^^^^^^^^
    |   File "C:\Users\user1\PycharmProjects\AsyncAwait\.venv\Lib\site-packages\fastapi\routing.py", line 387, in app
    |     raw_response = await run_endpoint_function(
    |                    ^^^^^^^^^^^^^^^^^^^^^^^^^^^^
    |     ...<3 lines>...
    |     )
    |     ^
    |   File "C:\Users\user1\PycharmProjects\AsyncAwait\.venv\Lib\site-packages\fastapi\routing.py", line 290, in run_endpoint_function
    |     return await run_in_threadpool(dependant.call, **values)
    |            ^^^^^^^^^^^^^^^^^^^^^^^^^^^^^^^^^^^^^^^^^^^^^^^^^
    |   File "C:\Users\user1\PycharmProjects\AsyncAwait\.venv\Lib\site-packages\starlette\concurrency.py", line 38, in run_in_threadpool
    |     return await anyio.to_thread.run_sync(func)
    |            ^^^^^^^^^^^^^^^^^^^^^^^^^^^^^^^^^^^^
    |   File "C:\Users\user1\PycharmProjects\AsyncAwait\.venv\Lib\site-packages\anyio\to_thread.py", line 56, in run_sync
    |     return await get_async_backend().run_sync_in_worker_thread(
    |            ^^^^^^^^^^^^^^^^^^^^^^^^^^^^^^^^^^^^^^^^^^^^^^^^^^^^
    |         func, args, abandon_on_cancel=abandon_on_cancel, limiter=limiter
    |         ^^^^^^^^^^^^^^^^^^^^^^^^^^^^^^^^^^^^^^^^^^^^^^^^^^^^^^^^^^^^^^^^
    |     )
    |     ^
    |   File "C:\Users\user1\PycharmProjects\AsyncAwait\.venv\Lib\site-packages\anyio\_backends\_asyncio.py", line 2485, in run_sync_in_worker_thread
    |     return await future
    |            ^^^^^^^^^^^^
    |   File "C:\Users\user1\PycharmProjects\AsyncAwait\.venv\Lib\site-packages\anyio\_backends\_asyncio.py", line 976, in run
    |     result = context.run(func, *args)
    |   File "C:\Users\user1\PycharmProjects\AsyncAwait\middleware.py", line 44, in error_demo
    |     raise ValueError("Simulated error for testing logs")
    | ValueError: Simulated error for testing logs
    +------------------------------------

During handling of the above exception, another exception occurred:

Traceback (most recent call last):
  File "C:\Users\user1\PycharmProjects\AsyncAwait\.venv\Lib\site-packages\starlette\middleware\errors.py", line 164, in __call__
    await self.app(scope, receive, _send)
  File "C:\Users\user1\PycharmProjects\AsyncAwait\.venv\Lib\site-packages\starlette\middleware\base.py", line 182, in __call__
    with recv_stream, send_stream, collapse_excgroups():
                                   ~~~~~~~~~~~~~~~~~~^^
  File "C:\Users\user1\AppData\Local\Programs\Python\Python313\Lib\contextlib.py", line 162, in __exit__
    self.gen.throw(value)
    ~~~~~~~~~~~~~~^^^^^^^
  File "C:\Users\user1\PycharmProjects\AsyncAwait\.venv\Lib\site-packages\starlette\_utils.py", line 85, in collapse_excgroups
    raise exc
  File "C:\Users\user1\PycharmProjects\AsyncAwait\.venv\Lib\site-packages\starlette\middleware\base.py", line 184, in __call__
    response = await self.dispatch_func(request, call_next)
               ^^^^^^^^^^^^^^^^^^^^^^^^^^^^^^^^^^^^^^^^^^^^
  File "C:\Users\user1\PycharmProjects\AsyncAwait\middleware.py", line 27, in log_requests
    raise e
  File "C:\Users\user1\PycharmProjects\AsyncAwait\middleware.py", line 21, in log_requests
    response = await call_next(request)
               ^^^^^^^^^^^^^^^^^^^^^^^^
  File "C:\Users\user1\PycharmProjects\AsyncAwait\.venv\Lib\site-packages\starlette\middleware\base.py", line 159, in call_next
    raise app_exc
  File "C:\Users\user1\PycharmProjects\AsyncAwait\.venv\Lib\site-packages\starlette\middleware\base.py", line 144, in coro
    await self.app(scope, receive_or_disconnect, send_no_error)
  File "C:\Users\user1\PycharmProjects\AsyncAwait\.venv\Lib\site-packages\starlette\middleware\exceptions.py", line 63, in __call__
    await wrap_app_handling_exceptions(self.app, conn)(scope, receive, send)
  File "C:\Users\user1\PycharmProjects\AsyncAwait\.venv\Lib\site-packages\starlette\_exception_handler.py", line 53, in wrapped_app
    raise exc
  File "C:\Users\user1\PycharmProjects\AsyncAwait\.venv\Lib\site-packages\starlette\_exception_handler.py", line 42, in wrapped_app
    await app(scope, receive, sender)
  File "C:\Users\user1\PycharmProjects\AsyncAwait\.venv\Lib\site-packages\fastapi\middleware\asyncexitstack.py", line 18, in __call__
    await self.app(scope, receive, send)
  File "C:\Users\user1\PycharmProjects\AsyncAwait\.venv\Lib\site-packages\starlette\routing.py", line 716, in __call__
    await self.middleware_stack(scope, receive, send)
  File "C:\Users\user1\PycharmProjects\AsyncAwait\.venv\Lib\site-packages\starlette\routing.py", line 736, in app
    await route.handle(scope, receive, send)
  File "C:\Users\user1\PycharmProjects\AsyncAwait\.venv\Lib\site-packages\starlette\routing.py", line 290, in handle
    await self.app(scope, receive, send)
  File "C:\Users\user1\PycharmProjects\AsyncAwait\.venv\Lib\site-packages\fastapi\routing.py", line 123, in app
    await wrap_app_handling_exceptions(app, request)(scope, receive, send)
  File "C:\Users\user1\PycharmProjects\AsyncAwait\.venv\Lib\site-packages\starlette\_exception_handler.py", line 53, in wrapped_app
    raise exc
  File "C:\Users\user1\PycharmProjects\AsyncAwait\.venv\Lib\site-packages\starlette\_exception_handler.py", line 42, in wrapped_app
    await app(scope, receive, sender)
  File "C:\Users\user1\PycharmProjects\AsyncAwait\.venv\Lib\site-packages\fastapi\routing.py", line 109, in app
    response = await f(request)
               ^^^^^^^^^^^^^^^^
  File "C:\Users\user1\PycharmProjects\AsyncAwait\.venv\Lib\site-packages\fastapi\routing.py", line 387, in app
    raw_response = await run_endpoint_function(
                   ^^^^^^^^^^^^^^^^^^^^^^^^^^^^
    ...<3 lines>...
    )
    ^
  File "C:\Users\user1\PycharmProjects\AsyncAwait\.venv\Lib\site-packages\fastapi\routing.py", line 290, in run_endpoint_function
    return await run_in_threadpool(dependant.call, **values)
           ^^^^^^^^^^^^^^^^^^^^^^^^^^^^^^^^^^^^^^^^^^^^^^^^^
  File "C:\Users\user1\PycharmProjects\AsyncAwait\.venv\Lib\site-packages\starlette\concurrency.py", line 38, in run_in_threadpool
    return await anyio.to_thread.run_sync(func)
           ^^^^^^^^^^^^^^^^^^^^^^^^^^^^^^^^^^^^
  File "C:\Users\user1\PycharmProjects\AsyncAwait\.venv\Lib\site-packages\anyio\to_thread.py", line 56, in run_sync
    return await get_async_backend().run_sync_in_worker_thread(
           ^^^^^^^^^^^^^^^^^^^^^^^^^^^^^^^^^^^^^^^^^^^^^^^^^^^^
        func, args, abandon_on_cancel=abandon_on_cancel, limiter=limiter
        ^^^^^^^^^^^^^^^^^^^^^^^^^^^^^^^^^^^^^^^^^^^^^^^^^^^^^^^^^^^^^^^^
    )
    ^
  File "C:\Users\user1\PycharmProjects\AsyncAwait\.venv\Lib\site-packages\anyio\_backends\_asyncio.py", line 2485, in run_sync_in_worker_thread
    return await future
           ^^^^^^^^^^^^
  File "C:\Users\user1\PycharmProjects\AsyncAwait\.venv\Lib\site-packages\anyio\_backends\_asyncio.py", line 976, in run
    result = context.run(func, *args)
  File "C:\Users\user1\PycharmProjects\AsyncAwait\middleware.py", line 44, in error_demo
    raise ValueError("Simulated error for testing logs")
ValueError: Simulated error for testing logs

2025-10-09 10:57:48,927 | INFO | GET / | Status: 200 | Duration: 0.001s | Visits: 1
2025-10-09 10:58:07,288 | INFO | GET /students | Status: 200 | Duration: 0.0s | Visits: 2
2025-10-09 10:58:15,413 | INFO | GET /count | Status: 404 | Duration: 0.0s | Visits: 3
2025-10-09 10:58:39,994 | INFO | GET /visits | Status: 200 | Duration: 0.0s | Visits: 4
2025-10-09 10:59:30,500 | ERROR | Exception in GET /error-demo: This is a test error
Traceback (most recent call last):
  File "C:\Users\user1\PycharmProjects\AsyncAwait\.venv\Lib\site-packages\starlette\middleware\base.py", line 151, in call_next
    message = await recv_stream.receive()
              ^^^^^^^^^^^^^^^^^^^^^^^^^^^
  File "C:\Users\user1\PycharmProjects\AsyncAwait\.venv\Lib\site-packages\anyio\streams\memory.py", line 111, in receive
    return self.receive_nowait()
           ~~~~~~~~~~~~~~~~~~~^^
  File "C:\Users\user1\PycharmProjects\AsyncAwait\.venv\Lib\site-packages\anyio\streams\memory.py", line 104, in receive_nowait
    raise EndOfStream
anyio.EndOfStream

During handling of the above exception, another exception occurred:

Traceback (most recent call last):
  File "C:\Users\user1\PycharmProjects\AsyncAwait\countVisits_task.py", line 26, in log_requests
    response = await call_next(request)
               ^^^^^^^^^^^^^^^^^^^^^^^^
  File "C:\Users\user1\PycharmProjects\AsyncAwait\.venv\Lib\site-packages\starlette\middleware\base.py", line 159, in call_next
    raise app_exc
  File "C:\Users\user1\PycharmProjects\AsyncAwait\.venv\Lib\site-packages\starlette\middleware\base.py", line 144, in coro
    await self.app(scope, receive_or_disconnect, send_no_error)
  File "C:\Users\user1\PycharmProjects\AsyncAwait\.venv\Lib\site-packages\starlette\middleware\exceptions.py", line 63, in __call__
    await wrap_app_handling_exceptions(self.app, conn)(scope, receive, send)
  File "C:\Users\user1\PycharmProjects\AsyncAwait\.venv\Lib\site-packages\starlette\_exception_handler.py", line 53, in wrapped_app
    raise exc
  File "C:\Users\user1\PycharmProjects\AsyncAwait\.venv\Lib\site-packages\starlette\_exception_handler.py", line 42, in wrapped_app
    await app(scope, receive, sender)
  File "C:\Users\user1\PycharmProjects\AsyncAwait\.venv\Lib\site-packages\fastapi\middleware\asyncexitstack.py", line 18, in __call__
    await self.app(scope, receive, send)
  File "C:\Users\user1\PycharmProjects\AsyncAwait\.venv\Lib\site-packages\starlette\routing.py", line 716, in __call__
    await self.middleware_stack(scope, receive, send)
  File "C:\Users\user1\PycharmProjects\AsyncAwait\.venv\Lib\site-packages\starlette\routing.py", line 736, in app
    await route.handle(scope, receive, send)
  File "C:\Users\user1\PycharmProjects\AsyncAwait\.venv\Lib\site-packages\starlette\routing.py", line 290, in handle
    await self.app(scope, receive, send)
  File "C:\Users\user1\PycharmProjects\AsyncAwait\.venv\Lib\site-packages\fastapi\routing.py", line 123, in app
    await wrap_app_handling_exceptions(app, request)(scope, receive, send)
  File "C:\Users\user1\PycharmProjects\AsyncAwait\.venv\Lib\site-packages\starlette\_exception_handler.py", line 53, in wrapped_app
    raise exc
  File "C:\Users\user1\PycharmProjects\AsyncAwait\.venv\Lib\site-packages\starlette\_exception_handler.py", line 42, in wrapped_app
    await app(scope, receive, sender)
  File "C:\Users\user1\PycharmProjects\AsyncAwait\.venv\Lib\site-packages\fastapi\routing.py", line 109, in app
    response = await f(request)
               ^^^^^^^^^^^^^^^^
  File "C:\Users\user1\PycharmProjects\AsyncAwait\.venv\Lib\site-packages\fastapi\routing.py", line 387, in app
    raw_response = await run_endpoint_function(
                   ^^^^^^^^^^^^^^^^^^^^^^^^^^^^
    ...<3 lines>...
    )
    ^
  File "C:\Users\user1\PycharmProjects\AsyncAwait\.venv\Lib\site-packages\fastapi\routing.py", line 288, in run_endpoint_function
    return await dependant.call(**values)
           ^^^^^^^^^^^^^^^^^^^^^^^^^^^^^^
  File "C:\Users\user1\PycharmProjects\AsyncAwait\countVisits_task.py", line 50, in error_demo
    raise Exception("This is a test error")
Exception: This is a test error

2025-10-09 11:00:20,840 | INFO | GET /visits | Status: 200 | Duration: 0.001s | Visits: 1
2025-10-09 11:00:26,539 | INFO | GET /visits | Status: 200 | Duration: 0.001s | Visits: 2
2025-10-09 15:00:28,318 | INFO | Duration: 5.0046 seconds
2025-10-09 15:00:31,395 | INFO | Fetching all students from database...
2025-10-09 15:00:33,446 | INFO | Duration: 5.0079 seconds
2025-10-09 15:00:36,410 | INFO | Duration: 5.0168 seconds
2025-10-09 15:00:41,586 | INFO | Duration: 5.0033 seconds
2025-10-09 15:02:11,350 | INFO | Fetching all students from database...
2025-10-09 15:02:16,354 | INFO | Duration: 5.0083 seconds
